Workbook

Sheet Сводка
A1: ЦЕНТР РАКЕТОЧНЫХ ВИДОВ СПОРТА, СПб — ФИНАНСОВАЯ МОДЕЛЬ v3 (10 ЛЕТ)
A3: Здание 2100 м² + антресоль 250 м² (каркас, потолок 8 м), земля бесплатно, собственные инвестиции.
A4: Композиция кортов — результат перебора 182 вариантов по критерию окупаемости (лист «Оптимизация»).
A6: ВЫБРАННАЯ КОМПОЗИЦИЯ
A7: Панорамных падел-кортов | B7: =Допущения!$B$6 -> 5
A8: Сингл падел-кортов | B8: =Допущения!$B$7 -> 0 | C8: Сингл невыгоден при 80% гонорара тренеру — выпал из оптимума
A9: Бадминтонных кортов | B9: =Допущения!$B$8 -> 4
A10: Столов настольного тенниса | B10: =Допущения!$B$9 -> 2 | C10: НТ сокращён с 4 до 2: слабейшая выручка на м²
A11: ИТОГО ИНВЕСТИЦИИ, ₽ | B11: =CAPEX!$B$26 -> 2.516352e+08
A13: РЕЗУЛЬТАТЫ ПО СЦЕНАРИЯМ
B14: Оптимистичный | C14: Средний | D14: Пессимистичный
A15: Выручка год 3, млн ₽ | B15: 217.26169 | C15: 183.47708 | D15: 139.96077
A16: EBITDA год 3, млн ₽ | B16: 106.25558 | C16: 80.358295 | D16: 46.506056
A17: Окупаемость от старта, лет | B17: 4.1200023 | C17: 4.9510358 | D17: 7.1417372
A18: NPV @18% с ТС, млн ₽ | B18: 350.79887 | C18: 197.87063 | D18: 2.6850013
A19: IRR с ТС | B19: 0.38884459 | C19: 0.30610934 | D19: 0.18198976
A21: ЖИВЫЕ МЕТРИКИ АКТИВНОГО СЦЕНАРИЯ (переключатель — лист «Допущения»)
A22: Окупаемость от старта, лет | B22: =ДДС!$B$20 -> 4.9510358
A23: Окупаемость от открытия, лет | B23: =ДДС!$B$19 -> 3.9510358
A24: NPV @18% с ТС, ₽ | B24: =ДДС!$B$15 -> 1.9787063e+08
A25: IRR с ТС | B25: =ДДС!$B$17 -> 0.30610934
A26: EBITDA год 3, ₽ | B26: =PL!E24 -> 80358295
A28: КЛЮЧЕВЫЕ РИСКИ И ОГОВОРКИ
A29: 1. Групповые программы дают ~30% валовой прибыли кортов; заполняемость групп (падел 8, бадминтон 12 чел) — главный операционный риск. Стресс-тест — лист «Оптимизация».
A30: 2. УСН: остаточная стоимость ОС ~245 млн превышает лимит 200 млн — требуется структурирование (2 юрлица или ОСНО со льготой ст. 149 НК для спортуслуг). В модели — УСН Д−Р 7% с мин. налогом 1%.
A31: 3. Сдельные тренеры получают 80% выручки инд. тренировок — клуб зарабатывает на этих часах в основном через аренду корта (тренировочная маржа всего 20%).
A32: 4. B2B-пакеты учтены внутри загрузки кортов — отдельной строки нет, двойного счёта нет.
A33: 5. Пессимистичный сценарий: окупаемость 7,1 года, NPV ≈ 0 — проект возвращает деньги, но не создаёт стоимости при ставке 18%.
A34: 6. Конкурентная волна СПб-2026 (Астра, Арсенал, Lunda, ТРК «Лето») — окно входа 12–24 мес; детальное обоснование — «Исследование рынка».

Sheet Допущения
A1: ДОПУЩЕНИЯ МОДЕЛИ v3 — ЦЕНТР РАКЕТОЧНЫХ ВИДОВ СПОРТА (10 ЛЕТ, 3 СЦЕНАРИЯ)
A3: Синие ячейки — входные параметры; их изменение пересчитывает модель. | C3: Каркасное здание 2100 м² + антресоль 250 м², земля бесплатно, собственные средства
A5: ОБЪЕКТ И РЕЖИМ РАБОТЫ
A6: Панорамных падел-кортов | B6: 5 | C6: Оптимум перебора 182 композиций — лист «Оптимизация»
A7: Сингл падел-кортов (1×1) | B7: 0 | C7: Сингл выпал из оптимума: при 80% гонорара тренеру и группах на панорамиках
A8: Бадминтонных кортов | B8: 4
A9: Столов настольного тенниса | B9: 2
A10: Часов работы в день | B10: 16 | C10: 07:00–23:00
A11: Рабочих дней в году | B11: 360
A12: Потолок загрузки | B12: 0.92 | C12: Технический максимум продаваемых часов
A14: СЦЕНАРИЙ (1 — оптимистичный, 2 — средний, 3 — пессимистичный)
A15: ПЕРЕКЛЮЧАТЕЛЬ СЦЕНАРИЯ | B15: 2 | C15: Меняйте 1/2/3 — пересчитывается вся модель
A16: Множители сценариев: | C16: Загрузка | D16: Цены | E16: Спрос (шоп/события/академия/ОФП)
A17: Оптимистичный | C17: 1.15 | D17: 1.05 | E17: 1.15
A18: Средний | C18: 1 | D18: 1 | E18: 1
A19: Пессимистичный | C19: 0.8 | D19: 0.95 | E19: 0.8
A20: Активный множитель загрузки | B20: =INDEX(C17:C19,Допущения!$B$15) -> 1
A21: Активный множитель цен | B21: =INDEX(D17:D19,Допущения!$B$15) -> 1
A22: Активный множитель спроса | B22: =INDEX(E17:E19,Допущения!$B$15) -> 1
A24: ИНДЕКСАЦИЯ, НАЛОГИ, ФИНАНСЫ
A25: Индексация цен (с года 2) | B25: 0.05
A26: Индексация расходов (с года 2) | B26: 0.06
A27: Индексация электроэнергии | B27: 0.07
A28: УСН «доходы − расходы» (СПб) | B28: 0.07 | C28: CAPEX списывается в год ввода; риск лимита ОС 200 млн — см. Сводку
A29: Минимальный налог (от доходов) | B29: 0.01
A30: Страховые взносы (эфф., МСП) | B30: 0.23 | C30: Только штатный ФОТ; самозанятые тренеры — без взносов
A31: Платёжная комиссия (СБП-микс) | B31: 0.01
A32: Доля безналичной выручки | B32: 0.9
A33: НДС на неосвобождённые потоки | B33: 0.05 | C33: Кафе, pro-shop, события; спортуслуги освобождены (ст. 149 НК)
A34: Ставка дисконтирования | B34: 0.18
A35: EV/EBITDA для терминальной стоимости | B35: 5
A37: Показатель | C37: Год 1 | D37: Год 2 | E37: Год 3 | F37: Год 4 | G37: Год 5 | H37: Год 6 | I37: Год 7 | J37: Год 8 | K37: Год 9 | L37: Год 10
A38: Индекс цен базовый (без сценария) | C38: =(1+Допущения!$B$25)^0 -> 1 | D38: =(1+Допущения!$B$25)^1 -> 1.05 | E38: =(1+Допущения!$B$25)^2 -> 1.1025 | F38: =(1+Допущения!$B$25)^3 -> 1.157625 | G38: =(1+Допущения!$B$25)^4 -> 1.2155063 | H38: =(1+Допущения!$B$25)^5 -> 1.2762816 | I38: =(1+Допущения!$B$25)^6 -> 1.3400956 | J38: =(1+Допущения!$B$25)^7 -> 1.4071004 | K38: =(1+Допущения!$B$25)^8 -> 1.4774554 | L38: =(1+Допущения!$B$25)^9 -> 1.5513282
A39: Индекс цен сценарный | C39: =C38*Допущения!$B$21 -> 1 | D39: =D38*Допущения!$B$21 -> 1.05 | E39: =E38*Допущения!$B$21 -> 1.1025 | F39: =F38*Допущения!$B$21 -> 1.157625 | G39: =G38*Допущения!$B$21 -> 1.2155063 | H39: =H38*Допущения!$B$21 -> 1.2762816 | I39: =I38*Допущения!$B$21 -> 1.3400956 | J39: =J38*Допущения!$B$21 -> 1.4071004 | ... L39: =L38*Допущения!$B$21 -> 1.5513282
A40: Индекс расходов | C40: =(1+Допущения!$B$26)^0 -> 1 | D40: =(1+Допущения!$B$26)^1 -> 1.06 | E40: =(1+Допущения!$B$26)^2 -> 1.1236 | F40: =(1+Допущения!$B$26)^3 -> 1.191016 | G40: =(1+Допущения!$B$26)^4 -> 1.262477 | H40: =(1+Допущения!$B$26)^5 -> 1.3382256 | I40: =(1+Допущения!$B$26)^6 -> 1.4185191 | J40: =(1+Допущения!$B$26)^7 -> 1.5036303 | K40: =(1+Допущения!$B$26)^8 -> 1.5938481 | L40: =(1+Допущения!$B$26)^9 -> 1.689479
A41: Индекс электроэнергии | C41: =(1+Допущения!$B$27)^0 -> 1 | D41: =(1+Допущения!$B$27)^1 -> 1.07 | E41: =(1+Допущения!$B$27)^2 -> 1.1449 | F41: =(1+Допущения!$B$27)^3 -> 1.225043 | G41: =(1+Допущения!$B$27)^4 -> 1.310796 | H41: =(1+Допущения!$B$27)^5 -> 1.4025517 | I41: =(1+Допущения!$B$27)^6 -> 1.5007304 | J41: =(1+Допущения!$B$27)^7 -> 1.6057815 | K41: =(1+Допущения!$B$27)^8 -> 1.7181862 | L41: =(1+Допущения!$B$27)^9 -> 1.8384592
A43: ЦЕНЫ АРЕНДЫ ГОДА 1, ₽/ЧАС
A44: Панорамик: пик | B44: 4700
A45: Панорамик: непик | B45: 2500
A46: Панорамик: доля пиковых часов | B46: 0.55
...

Sheet CAPEX
A1: ИНВЕСТИЦИИ, ₽ — СОБСТВЕННЫЕ СРЕДСТВА, ЗЕМЛЯ БЕСПЛАТНО
A3: Статья | B3: Сумма, ₽
A4: Проектирование, ИРД, экспертиза | B4: 6000000
A5: Участок: фундаменты, благоустройство, парковка | B5: 16000000
A6: Металлокаркас и сэндвич-панели (тёплый контур, 2100 м²) | B6: 84000000
A7: Антресоль 250 м² (ОФП, детская, лаунж) | B7: 7000000
A8: Полы и спортивные покрытия | B8: 11000000
A9: Вентиляция с рекуперацией + VRF (отопление/охлаждение) | B9: 27000000
A10: Электроснабжение и спортивное LED-освещение | B10: 12500000
A11: Водоснабжение и канализация | B11: 6000000
A12: Слаботочные системы, СКУД, видео | B12: 5000000
A13: Противопожарные системы | B13: 4000000
A14: Технологическое присоединение | B14: 8000000
A15: Раздевалки, мебель, ресепшн, кафе, киоски | B15: 14000000
... A17: Брендинг, предзапусковый маркетинг и преселл | B17: 4000000
A18: Падел-корты панорамные | B18: =3000000*Допущения!$B$6 -> 15000000 | C18: 3,0 млн/шт при заказе партии
A19: Падел сингл-корты | B19: =2200000*Допущения!$B$7 -> 0 | C19: 2,2 млн/шт
A20: Оборудование бадминтона | B20: =200000*Допущения!$B$8 -> 800000 | C20: 200 тыс/корт
A21: Столы НТ премиум и инвентарь | B21: =320000*Допущения!$B$9 -> 640000 | C21: 320 тыс/стол
A22: Итого строительство и оснащение | B22: =SUM(B4:B21) -> 227440000
A23: Непредвиденные, % | B23: 0.08
A24: Строительство с непредвиденными | B24: =B22*(1+B23) -> 2.456352e+08 | C24: База поддерживающего CAPEX и списания на УСН
A25: Оборотный капитал на запуск | B25: 6000000
A26: ИТОГО ИНВЕСТИЦИИ | B26: =B24+B25 -> 2.516352e+08

Sheet Персонал
A1: ПЕРСОНАЛ: ШТАТ НА ОКЛАДАХ; СДЕЛЬНЫЕ ТРЕНЕРЫ — В ПРЯМЫХ РАСХОДАХ ПРОГРАММ
A3: Должность | B3: Оклад, ₽/мес | C3: Кол-во | D3: ФОТ, ₽/мес | E3: Взносы
A4: Управляющий | B4: 220000 | C4: 1 | D4: =B4*C4 -> 220000 | E4: да
A5: Администраторы ресепшн | B5: 75000 | C5: 3 | D5: =B5*C5 -> 225000 | E5: да
A6: Старшие тренеры направлений | B6: 130000 | C6: 3 | D6: =B6*C6 -> 390000 | E6: да
A7: Менеджер B2B и событий | B7: 90000 | C7: 1 | D7: =B7*C7 -> 90000 | E7: да
A8: Сотрудники кафе | B8: 65000 | C8: 2 | D8: =B8*C8 -> 130000 | E8: да
A9: Уборка и хозблок | B9: 60000 | C9: 1 | D9: =B9*C9 -> 60000 | E9: да
A10: Маркетолог (SMM, аутсорс) | B10: 100000 | C10: 1 | D10: =B10*C10 -> 100000 | E10: нет (аутсорс)
A11: Техник-инженер | B11: 85000 | C11: 1 | D11: =B11*C11 -> 85000 | E11: да
A12: Штатный ФОТ, ₽/мес (взносооблагаемый) | B12: =SUMIF(E4:E11,"да",D4:D11) -> 1200000 | C12: 3 главных тренера направлений — в штате на окладах
A13: Аутсорс (SMM), ₽/мес | B13: =SUMIF(E4:E11,"нет (аутсорс)",D4:D11) -> 100000
A15: Показатель | C15: Год 1 | D15: Год 2 | E15: Год 3 | F15: Год 4 | G15: Год 5 | H15: Год 6 | I15: Год 7 | J15: Год 8 | K15: Год 9 | L15: Год 10
A16: ФОТ + аутсорс, ₽/год | C16: =(Персонал!$B$12+Персонал!$B$13)*12*Допущения!C40 -> 15600000 | D16: =(Персонал!$B$12+Персонал!$B$13)*12*Допущения!D40 -> 16536000 | E16: =(Персонал!$B$12+Персонал!$B$13)*12*Допущения!E40 -> 17528160 | F16: =(Персонал!$B$12+Персонал!$B$13)*12*Допущения!F40 -> 18579850 | G16: =(Персонал!$B$12+Персонал!$B$13)*12*Допущения!G40 -> 19694641 | H16: =(Персонал!$B$12+Персонал!$B$13)*12*Допущения!H40 -> 20876319 | I16: =(Персонал!$B$12+Персонал!$B$13)*12*Допущения!I40 -> 22128898 | J16: =(Персонал!$B$12+Персонал!$B$13)*12*Допущения!J40 -> 23456632 | ... L16: =(Персонал!$B$12+Персонал!$B$13)*12*Допущения!L40 -> 26355872
A17: Страховые взносы, ₽/год | C17: =Персонал!$B$12*12*Допущения!C40*Допущения!$B$30 -> 3312000 | D17: =Персонал!$B$12*12*Допущения!D40*Допущения!$B$30 -> 3510720 | E17: =Персонал!$B$12*12*Допущения!E40*Допущения!$B$30 -> 3721363.2 | F17: =Персонал!$B$12*12*Допущения!F40*Допущения!$B$30 -> 3944645 | G17: =Персонал!$B$12*12*Допущения!G40*Допущения!$B$30 -> 4181323.7 | H17: =Персонал!$B$12*12*Допущения!H40*Допущения!$B$30 -> 4432203.1 | I17: =Персонал!$B$12*12*Допущения!I40*Допущения!$B$30 -> 4698135.3 | J17: =Персонал!$B$12*12*Допущения!J40*Допущения!$B$30 -> 4980023.4 | ... L17: =Персонал!$B$12*12*Допущения!L40*Допущения!$B$30 -> 5595554.3

Sheet Выручка
A1: ВЫРУЧКА И ПРЯМЫЕ РАСХОДЫ ПРОГРАММ, ₽/ГОД
A3: Показатель | C3: Год 1 | D3: Год 2 | E3: Год 3 | F3: Год 4 | G3: Год 5 | H3: Год 6 | I3: Год 7 | J3: Год 8 | K3: Год 9 | L3: Год 10
A4: Детская академия: корт-часы
A5: Корт-часы академии, всего | C5: =Допущения!C99*Допущения!$B$106*Допущения!$B$105*Допущения!$B$102 -> 2538 | D5: =Допущения!D99*Допущения!$B$106*Допущения!$B$105*Допущения!$B$102 -> 3948 | E5: =Допущения!E99*Допущения!$B$106*Допущения!$B$105*Допущения!$B$102 -> 5076 | F5: =Допущения!F99*Допущения!$B$106*Допущения!$B$105*Допущения!$B$102 -> 5076 | G5: =Допущения!G99*Допущения!$B$106*Допущения!$B$105*Допущения!$B$102 -> 5076 | H5: =Допущения!H99*Допущения!$B$106*Допущения!$B$105*Допущения!$B$102 -> 5076 | I5: =Допущения!I99*Допущения!$B$106*Допущения!$B$105*Допущения!$B$102 -> 5076 | J5: =Допущения!J99*Допущения!$B$106*Допущения!$B$105*Допущения!$B$102 -> 5076 | ... L5: =Допущения!L99*Допущения!$B$106*Допущения!$B$105*Допущения!$B$102 -> 5076 | M5: Занятий/нед × кортов × 1,5 ч × 47 нед
A6: — на кортах: панорамики | C6: =C5*Допущения!$B$6/(Допущения!$B$6+Допущения!$B$8+Допущения!$B$9) -> 1153.6364 | D6: =D5*Допущения!$B$6/(Допущения!$B$6+Допущения!$B$8+Допущения!$B$9) -> 1794.5455 | E6: =E5*Допущения!$B$6/(Допущения!$B$6+Допущения!$B$8+Допущения!$B$9) -> 2307.2727 | F6: =F5*Допущения!$B$6/(Допущения!$B$6+Допущения!$B$8+Допущения!$B$9) -> 2307.2727 | G6: =G5*Допущения!$B$6/(Допущения!$B$6+Допущения!$B$8+Допущения!$B$9) -> 2307.2727 | H6: =H5*Допущения!$B$6/(Допущения!$B$6+Допущения!$B$8+Допущения!$B$9) -> 2307.2727 | I6: =I5*Допущения!$B$6/(Допущения!$B$6+Допущения!$B$8+Допущения!$B$9) -> 2307.2727 | J6: =J5*Допущения!$B$6/(Допущения!$B$6+Допущения!$B$8+Допущения!$B$9) -> 2307.2727 | ... L6: =L5*Допущения!$B$6/(Допущения!$B$6+Допущения!$B$8+Допущения!$B$9) -> 2307.2727
A7: — на кортах: бадминтон | C7: =C5*Допущения!$B$8/(Допущения!$B$6+Допущения!$B$8+Допущения!$B$9) -> 922.90909 | D7: =D5*Допущения!$B$8/(Допущения!$B$6+Допущения!$B$8+Допущения!$B$9) -> 1435.6364 | E7: =E5*Допущения!$B$8/(Допущения!$B$6+Допущения!$B$8+Допущения!$B$9) -> 1845.8182 | F7: =F5*Допущения!$B$8/(Допущения!$B$6+Допущения!$B$8+Допущения!$B$9) -> 1845.8182 | G7: =G5*Допущения!$B$8/(Допущения!$B$6+Допущения!$B$8+Допущения!$B$9) -> 1845.8182 | H7: =H5*Допущения!$B$8/(Допущения!$B$6+Допущения!$B$8+Допущения!$B$9) -> 1845.8182 | I7: =I5*Допущения!$B$8/(Допущения!$B$6+Допущения!$B$8+Допущения!$B$9) -> 1845.8182 | J7: =J5*Допущения!$B$8/(Допущения!$B$6+Допущения!$B$8+Допущения!$B$9) -> 1845.8182 | ... L7: =L5*Допущения!$B$8/(Допущения!$B$6+Допущения!$B$8+Допущения!$B$9) -> 1845.8182
A8: — на кортах: настольный теннис | C8: =C5*Допущения!$B$9/(Допущения!$B$6+Допущения!$B$8+Допущения!$B$9) -> 461.45455 | D8: =D5*Допущения!$B$9/(Допущения!$B$6+Допущения!$B$8+Допущения!$B$9) -> 717.81818 | E8: =E5*Допущения!$B$9/(Допущения!$B$6+Допущения!$B$8+Допущения!$B$9) -> 922.90909 | F8: =F5*Допущения!$B$9/(Допущения!$B$6+Допущения!$B$8+Допущения!$B$9) -> 922.90909 | G8: =G5*Допущения!$B$9/(Допущения!$B$6+Допущения!$B$8+Допущения!$B$9) -> 922.90909 | H8: =H5*Допущения!$B$9/(Допущения!$B$6+Допущения!$B$8+Допущения!$B$9) -> 922.90909 | I8: =I5*Допущения!$B$9/(Допущения!$B$6+Допущения!$B$8+Допущения!$B$9) -> 922.90909 | J8: =J5*Допущения!$B$9/(Допущения!$B$6+Допущения!$B$8+Допущения!$B$9) -> 922.90909 | ... L8: =L5*Допущения!$B$9/(Допущения!$B$6+Допущения!$B$8+Допущения!$B$9) -> 922.90909
A9: Панорамики
A10: Фонд часов (за вычетом академии) | C10: =Допущения!$B$6*Допущения!$B$10*Допущения!$B$11-C6 -> 27646.364 | D10: =Допущения!$B$6*Допущения!$B$10*Допущения!$B$11-D6 -> 27005.455 | E10: =Допущения!$B$6*Допущения!$B$10*Допущения!$B$11-E6 -> 26492.727 | F10: =Допущения!$B$6*Допущения!$B$10*Допущения!$B$11-F6 -> 26492.727 | G10: =Допущения!$B$6*Допущения!$B$10*Допущения!$B$11-G6 -> 26492.727 | H10: =Допущения!$B$6*Допущения!$B$10*Допущения!$B$11-H6 -> 26492.727 | I10: =Допущения!$B$6*Допущения!$B$10*Допущения!$B$11-I6 -> 26492.727 | J10: =Допущения!$B$6*Допущения!$B$10*Допущения!$B$11-J6 -> 26492.727 | ... L10: =Допущения!$B$6*Допущения!$B$10*Допущения!$B$11-L6 -> 26492.727
A11: Загрузка (со сценарием) | C11: =MIN(Допущения!C63*Допущения!$B$20,Допущения!$B$12) -> 0.38 | D11: =MIN(Допущения!D63*Допущения!$B$20,Допущения!$B$12) -> 0.52 | E11: =MIN(Допущения!E63*Допущения!$B$20,Допущения!$B$12) -> 0.55 | F11: =MIN(Допущения!F63*Допущения!$B$20,Допущения!$B$12) -> 0.57 | G11: =MIN(Допущения!G63*Допущения!$B$20,Допущения!$B$12) -> 0.58 | H11: =MIN(Допущения!H63*Допущения!$B$20,Допущения!$B$12) -> 0.59 | I11: =MIN(Допущения!I63*Допущения!$B$20,Допущения!$B$12) -> 0.6 | J11: =MIN(Допущения!J63*Допущения!$B$20,Допущения!$B$12) -> 0.6 | ... L11: =MIN(Допущения!L63*Допущения!$B$20,Допущения!$B$12) -> 0.6
A12: Продано корт-часов | C12: =C10*C11 -> 10505.618 | D12: =D10*D11 -> 14042.836 | E12: =E10*E11 -> 14571 | F12: =F10*F11 -> 15100.855 | G12: =G10*G11 -> 15365.782 | H12: =H10*H11 -> 15630.709 | I12: =I10*I11 -> 15895.636 | J12: =J10*J11 -> 15895.636 | ... L12: =L10*L11 -> 15895.636
A13: Доля групповых (эфф.) | C13: =IF(Допущения!$B$6>=Допущения!$B$83,Допущения!$B$80,0) -> 0.3 | D13: =IF(Допущения!$B$6>=Допущения!$B$83,Допущения!$B$80,0) -> 0.3 | E13: =IF(Допущения!$B$6>=Допущения!$B$83,Допущения!$B$80,0) -> 0.3 | F13: =IF(Допущения!$B$6>=Допущения!$B$83,Допущения!$B$80,0) -> 0.3 | G13: =IF(Допущения!$B$6>=Допущения!$B$83,Допущения!$B$80,0) -> 0.3 | H13: =IF(Допущения!$B$6>=Допущения!$B$83,Допущения!$B$80,0) -> 0.3 | I13: =IF(Допущения!$B$6>=Допущения!$B$83,Допущения!$B$80,0) -> 0.3 | J13: =IF(Допущения!$B$6>=Допущения!$B$83,Допущения!$B$80,0) -> 0.3 | ... L13: =IF(Допущения!$B$6>=Допущения!$B$83,Допущения!$B$80,0) -> 0.3
A14: Аренда (свободная + под инд. тренировки) | C14: =C12*(1-C13)*Допущения!$B$47*Допущения!C39 -> 27283090 | D14: =D12*(1-D13)*Допущения!$B$47*Допущения!D39 -> 38292708 | E14: =E12*(1-E13)*Допущения!$B$47*Допущения!E39 -> 41719578 | F14: =F12*(1-F13)*Допущения!$B$47*Допущения!F39 -> 45398486 | G14: =G12*(1-G13)*Допущения!$B$47*Допущения!G39 -> 48504698 | H14: =H12*(1-H13)*Допущения!$B$47*Допущения!H39 -> 51808036 | I14: =I12*(1-I13)*Допущения!$B$47*Допущения!I39 -> 55320445 | J14: =J12*(1-J13)*Допущения!$B$47*Допущения!J39 -> 58086467 | ... L14: =L12*(1-L13)*Допущения!$B$47*Допущения!L39 -> 64040330
A15: Инд. тренировки (выручка клуба) | C15: =C12*Допущения!$B$70*Допущения!$B$74*Допущения!C39 -> 7879213.6 | D15: =D12*Допущения!$B$70*Допущения!$B$74*Допущения!D39 -> 11058734 | E15: =E12*Допущения!$B$70*Допущения!$B$74*Допущения!E39 -> 12048396 | F15: =F12*Допущения!$B$70*Допущения!$B$74*Допущения!F39 -> 13110845 | G15: =G12*Допущения!$B$70*Допущения!$B$74*Допущения!G39 -> 14007903 | H15: =H12*Допущения!$B$70*Допущения!$B$74*Допущения!H39 -> 14961889 | I15: =I12*Допущения!$B$70*Допущения!$B$74*Допущения!I39 -> 15976255 | J15: =J12*Допущения!$B$70*Допущения!$B$74*Допущения!J39 -> 16775067 | ... L15: =L12*Допущения!$B$70*Допущения!$B$74*Допущения!L39 -> 18494512
A16: гонорары инд. тренеров | C16: =-C15*Допущения!$B$77 -> -6303370.9 | D16: =-D15*Допущения!$B$77 -> -8846986.9 | E16: =-E15*Допущения!$B$77 -> -9638716.5 | F16: =-F15*Допущения!$B$77 -> -10488676 | G16: =-G15*Допущения!$B$77 -> -11206322 | H16: =-H15*Допущения!$B$77 -> -11969511 | I16: =-I15*Допущения!$B$77 -> -12781004 | J16: =-J15*Допущения!$B$77 -> -13420054 | ... L16: =-L15*Допущения!$B$77 -> -14795610
A17: Групповые занятия (выручка) | C17: =C12*C13*Допущения!$B$82*Допущения!$B$81/Допущения!$B$83*Допущения!C39 -> 23952809 | D17: =D12*D13*Допущения!$B$82*Допущения!$B$81/Допущения!$B$83*Допущения!D39 -> 33618550 | E17: =E12*E13*Допущения!$B$82*Допущения!$B$81/Допущения!$B$83*Допущения!E39 -> 36627123 | F17: =F12*F13*Допущения!$B$82*Допущения!$B$81/Допущения!$B$83*Допущения!F39 -> 39856969 | G17: =G12*G13*Допущения!$B$82*Допущения!$B$81/Допущения!$B$83*Допущения!G39 -> 42584025 | H17: =H12*H13*Допущения!$B$82*Допущения!$B$81/Допущения!$B$83*Допущения!H39 -> 45484144 | I17: =I12*I13*Допущения!$B$82*Допущения!$B$81/Допущения!$B$83*Допущения!I39 -> 48567814 | J17: =J12*J13*Допущения!$B$82*Допущения!$B$81/Допущения!$B$83*Допущения!J39 -> 50996205 | ... L17: =L12*L13*Допущения!$B$82*Допущения!$B$81/Допущения!$B$83*Допущения!L39 -> 56223316
A18: гонорары тренеров групп | C18: =-C12*C13*Допущения!$B$84/Допущения!$B$83*Допущения!C40 -> -6303370.9 | D18: =-D12*D13*Допущения!$B$84/Допущения!$B$83*Допущения!D40 -> -8931243.9 | E18: =-E12*E13*Допущения!$B$84/Допущения!$B$83*Допущения!E40 -> -9823185.4 | F18: =-F12*F13*Допущения!$B$84/Допущения!$B$83*Допущения!F40 -> -10791216 | G18: =-G12*G13*Допущения!$B$84/Допущения!$B$83*Допущения!G40 -> -11639367 | H18: =-H12*H13*Допущения!$B$84/Допущения!$B$83*Допущения!H40 -> -12550449 | I18: =-I12*I13*Допущения!$B$84/Допущения!$B$83*Допущения!I40 -> -13528958 | J18: =-J12*J13*Допущения!$B$84/Допущения!$B$83*Допущения!J40 -> -14340696 | ... L18: =-L12*L13*Допущения!$B$84/Допущения!$B$83*Допущения!L40 -> -16113206
A19: Сингл
A20: Фонд часов | C20: =Допущения!$B$7*Допущения!$B$10*Допущения!$B$11 -> 0 | D20: =Допущения!$B$7*Допущения!$B$10*Допущения!$B$11 -> 0 | E20: =Допущения!$B$7*Допущения!$B$10*Допущения!$B$11 -> 0 | F20: =Допущения!$B$7*Допущения!$B$10*Допущения!$B$11 -> 0 | G20: =Допущения!$B$7*Допущения!$B$10*Допущения!$B$11 -> 0 | H20: =Допущения!$B$7*Допущения!$B$10*Допущения!$B$11 -> 0 | I20: =Допущения!$B$7*Допущения!$B$10*Допущения!$B$11 -> 0 | J20: =Допущения!$B$7*Допущения!$B$10*Допущения!$B$11 -> 0 | ... L20: =Допущения!$B$7*Допущения!$B$10*Допущения!$B$11 -> 0
A21: Загрузка (со сценарием) | C21: =MIN(Допущения!C64*Допущения!$B$20,Допущения!$B$12) -> 0.32 | D21: =MIN(Допущения!D64*Допущения!$B$20,Допущения!$B$12) -> 0.45 | E21: =MIN(Допущения!E64*Допущения!$B$20,Допущения!$B$12) -> 0.48 | F21: =MIN(Допущения!F64*Допущения!$B$20,Допущения!$B$12) -> 0.5 | G21: =MIN(Допущения!G64*Допущения!$B$20,Допущения!$B$12) -> 0.51 | H21: =MIN(Допущения!H64*Допущения!$B$20,Допущения!$B$12) -> 0.52 | I21: =MIN(Допущения!I64*Допущения!$B$20,Допущения!$B$12) -> 0.53 | J21: =MIN(Допущения!J64*Допущения!$B$20,Допущения!$B$12) -> 0.53 | ... L21: =MIN(Допущения!L64*Допущения!$B$20,Допущения!$B$12) -> 0.53
A22: Продано корт-часов | C22: =C20*C21 -> 0 | D22: =D20*D21 -> 0 | E22: =E20*E21 -> 0 | F22: =F20*F21 -> 0 | G22: =G20*G21 -> 0 | H22: =H20*H21 -> 0 | I22: =I20*I21 -> 0 | J22: =J20*J21 -> 0 | ... L22: =L20*L21 -> 0
A23: Доля групповых (эфф.) | C23: =0 -> 0 | D23: =0 -> 0 | E23: =0 -> 0 | F23: =0 -> 0 | G23: =0 -> 0 | H23: =0 -> 0 | I23: =0 -> 0 | J23: =0 -> 0 | ... L23: =0 -> 0
A24: Аренда (свободная + под инд. тренировки) | C24: =C22*(1-C23)*Допущения!$B$51*Допущения!C39 -> 0 | D24: =D22*(1-D23)*Допущения!$B$51*Допущения!D39 -> 0 | E24: =E22*(1-E23)*Допущения!$B$51*Допущения!E39 -> 0 | F24: =F22*(1-F23)*Допущения!$B$51*Допущения!F39 -> 0 | G24: =G22*(1-G23)*Допущения!$B$51*Допущения!G39 -> 0 | H24: =H22*(1-H23)*Допущения!$B$51*Допущения!H39 -> 0 | I24: =I22*(1-I23)*Допущения!$B$51*Допущения!I39 -> 0 | J24: =J22*(1-J23)*Допущения!$B$51*Допущения!J39 -> 0 | ... L24: =L22*(1-L23)*Допущения!$B$51*Допущения!L39 -> 0
A25: Инд. тренировки (выручка клуба) | C25: =C22*Допущения!$B$71*Допущения!$B$74*Допущения!C39 -> 0 | D25: =D22*Допущения!$B$71*Допущения!$B$74*Допущения!D39 -> 0 | E25: =E22*Допущения!$B$71*Допущения!$B$74*Допущения!E39 -> 0 | F25: =F22*Допущения!$B$71*Допущения!$B$74*Допущения!F39 -> 0 | G25: =G22*Допущения!$B$71*Допущения!$B$74*Допущения!G39 -> 0 | H25: =H22*Допущения!$B$71*Допущения!$B$74*Допущения!H39 -> 0 | I25: =I22*Допущения!$B$71*Допущения!$B$74*Допущения!I39 -> 0 | J25: =J22*Допущения!$B$71*Допущения!$B$74*Допущения!J39 -> 0 | ... L25: =L22*Допущения!$B$71*Допущения!$B$74*Допущения!L39 -> 0
A26: гонорары инд. тренеров | C26: =-C25*Допущения!$B$77 -> 0 | D26: =-D25*Допущения!$B$77 -> 0 | E26: =-E25*Допущения!$B$77 -> 0 | F26: =-F25*Допущения!$B$77 -> 0 | G26: =-G25*Допущения!$B$77 -> 0 | H26: =-H25*Допущения!$B$77 -> 0 | I26: =-I25*Допущения!$B$77 -> 0 | J26: =-J25*Допущения!$B$77 -> 0 | ... L26: =-L25*Допущения!$B$77 -> 0
A27: Бадминтон
A28: Фонд часов (за вычетом академии) | C28: =Допущения!$B$8*Допущения!$B$10*Допущения!$B$11-C7 -> 22117.091 | D28: =Допущения!$B$8*Допущения!$B$10*Допущения!$B$11-D7 -> 21604.364 | E28: =Допущения!$B$8*Допущения!$B$10*Допущения!$B$11-E7 -> 21194.182 | F28: =Допущения!$B$8*Допущения!$B$10*Допущения!$B$11-F7 -> 21194.182 | G28: =Допущения!$B$8*Допущения!$B$10*Допущения!$B$11-G7 -> 21194.182 | H28: =Допущения!$B$8*Допущения!$B$10*Допущения!$B$11-H7 -> 21194.182 | I28: =Допущения!$B$8*Допущения!$B$10*Допущения!$B$11-I7 -> 21194.182 | J28: =Допущения!$B$8*Допущения!$B$10*Допущения!$B$11-J7 -> 21194.182 | ... L28: =Допущения!$B$8*Допущения!$B$10*Допущения!$B$11-L7 -> 21194.182
A29: Загрузка (со сценарием) | C29: =MIN(Допущения!C65*Допущения!$B$20,Допущения!$B$12) -> 0.3 | D29: =MIN(Допущения!D65*Допущения!$B$20,Допущения!$B$12) -> 0.4 | E29: =MIN(Допущения!E65*Допущения!$B$20,Допущения!$B$12) -> 0.45 | F29: =MIN(Допущения!F65*Допущения!$B$20,Допущения!$B$12) -> 0.47 | G29: =MIN(Допущения!G65*Допущения!$B$20,Допущения!$B$12) -> 0.48 | H29: =MIN(Допущения!H65*Допущения!$B$20,Допущения!$B$12) -> 0.49 | I29: =MIN(Допущения!I65*Допущения!$B$20,Допущения!$B$12) -> 0.5 | J29: =MIN(Допущения!J65*Допущения!$B$20,Допущения!$B$12) -> 0.5 | ... L29: =MIN(Допущения!L65*Допущения!$B$20,Допущения!$B$12) -> 0.5
A30: Продано корт-часов | C30: =C28*C29 -> 6635.1273 | D30: =D28*D29 -> 8641.7455 | E30: =E28*E29 -> 9537.3818 | F30: =F28*F29 -> 9961.2655 | G30: =G28*G29 -> 10173.207 | H30: =H28*H29 -> 10385.149 | I30: =I28*I29 -> 10597.091 | J30: =J28*J29 -> 10597.091 | ... L30: =L28*L29 -> 10597.091
A31: Доля групповых (эфф.) | C31: =IF(Допущения!$B$8>=Допущения!$B$88,Допущения!$B$85,0) -> 0.3 | D31: =IF(Допущения!$B$8>=Допущения!$B$88,Допущения!$B$85,0) -> 0.3 | E31: =IF(Допущения!$B$8>=Допущения!$B$88,Допущения!$B$85,0) -> 0.3 | F31: =IF(Допущения!$B$8>=Допущения!$B$88,Допущения!$B$85,0) -> 0.3 | G31: =IF(Допущения!$B$8>=Допущения!$B$88,Допущения!$B$85,0) -> 0.3 | H31: =IF(Допущения!$B$8>=Допущения!$B$88,Допущения!$B$85,0) -> 0.3 | I31: =IF(Допущения!$B$8>=Допущения!$B$88,Допущения!$B$85,0) -> 0.3 | J31: =IF(Допущения!$B$8>=Допущения!$B$88,Допущения!$B$85,0) -> 0.3 | ... L31: =IF(Допущения!$B$8>=Допущения!$B$88,Допущения!$B$85,0) -> 0.3
A32: Аренда (свободная + под инд. тренировки) | C32: =C30*(1-C31)*Допущения!$B$55*Допущения!C39 -> 6966883.6 | D32: =D30*(1-D31)*Допущения!$B$55*Допущения!D39 -> 9527524.4 | E32: =E30*(1-E31)*Допущения!$B$55*Допущения!E39 -> 11040712 | F32: =F30*(1-F31)*Допущения!$B$55*Допущения!F39 -> 12107980 | G32: =G30*(1-G31)*Допущения!$B$55*Допущения!G39 -> 12983877 | H32: =H30*(1-H31)*Допущения!$B$55*Допущения!H39 -> 13917093 | I32: =I30*(1-I31)*Допущения!$B$55*Допущения!I39 -> 14911171 | J32: =J30*(1-J31)*Допущения!$B$55*Допущения!J39 -> 15656730 | ... L32: =L30*(1-L31)*Допущения!$B$55*Допущения!L39 -> 17261544
A33: Инд. тренировки (выручка клуба) | C33: =C30*Допущения!$B$72*Допущения!$B$75*Допущения!C39 -> 2786753.5 | D33: =D30*Допущения!$B$72*Допущения!$B$75*Допущения!D39 -> 3811009.7 | E33: =E30*Допущения!$B$72*Допущения!$B$75*Допущения!E39 -> 4416284.7 | F33: =F30*Допущения!$B$72*Допущения!$B$75*Допущения!F39 -> 4843192.2 | G33: =G30*Допущения!$B$72*Допущения!$B$75*Допущения!G39 -> 5193550.7 | H33: =H30*Допущения!$B$72*Допущения!$B$75*Допущения!H39 -> 5566837.2 | I33: =I30*Допущения!$B$72*Допущения!$B$75*Допущения!I39 -> 5964468.4 | J33: =J30*Допущения!$B$72*Допущения!$B$75*Допущения!J39 -> 6262691.9 | ... L33: =L30*Допущения!$B$72*Допущения!$B$75*Допущения!L39 -> 6904617.8
A34: гонорары инд. тренеров | C34: =-C33*Допущения!$B$77 -> -2229402.8 | D34: =-D33*Допущения!$B$77 -> -3048807.8 | E34: =-E33*Допущения!$B$77 -> -3533027.7 | F34: =-F33*Допущения!$B$77 -> -3874553.7 | G34: =-G33*Допущения!$B$77 -> -4154840.6 | H34: =-H33*Допущения!$B$77 -> -4453469.8 | I34: =-I33*Допущения!$B$77 -> -4771574.8 | J34: =-J33*Допущения!$B$77 -> -5010153.5 | ... L34: =-L33*Допущения!$B$77 -> -5523694.2
A35: Групповые занятия (выручка) | C35: =C30*C31*Допущения!$B$87*Допущения!$B$86/Допущения!$B$88*Допущения!C39 -> 11943229 | D35: =D30*D31*Допущения!$B$87*Допущения!$B$86/Допущения!$B$88*Допущения!D39 -> 16332899 | E35: =E30*E31*Допущения!$B$87*Допущения!$B$86/Допущения!$B$88*Допущения!E39 -> 18926934 | F35: =F30*F31*Допущения!$B$87*Допущения!$B$86/Допущения!$B$88*Допущения!F39 -> 20756538 | G35: =G30*G31*Допущения!$B$87*Допущения!$B$86/Допущения!$B$88*Допущения!G39 -> 22258075 | H35: =H30*H31*Допущения!$B$87*Допущения!$B$86/Допущения!$B$88*Допущения!H39 -> 23857874 | I35: =I30*I31*Допущения!$B$87*Допущения!$B$86/Допущения!$B$88*Допущения!I39 -> 25562008 | J35: =J30*J31*Допущения!$B$87*Допущения!$B$86/Допущения!$B$88*Допущения!J39 -> 26840108 | ... L35: =L30*L31*Допущения!$B$87*Допущения!$B$86/Допущения!$B$88*Допущения!L39 -> 29591219
A36: гонорары тренеров групп | C36: =-C30*C31*Допущения!$B$89/Допущения!$B$88*Допущения!C40 -> -1990538.2 | D36: =-D30*D31*Допущения!$B$89/Допущения!$B$88*Допущения!D40 -> -2748075.1 | E36: =-E30*E31*Допущения!$B$89/Допущения!$B$88*Допущения!E40 -> -3214860.7 | F36: =-F30*F31*Допущения!$B$89/Допущения!$B$88*Допущения!F40 -> -3559208 | G36: =-G30*G31*Допущения!$B$89/Допущения!$B$88*Допущения!G40 -> -3853031.9 | H36: =-H30*H31*Допущения!$B$89/Допущения!$B$88*Допущения!H40 -> -4169301.6 | I36: =-I30*I31*Допущения!$B$89/Допущения!$B$88*Допущения!I40 -> -4509652.8 | J36: =-J30*J31*Допущения!$B$89/Допущения!$B$88*Допущения!J40 -> -4780232 | ... L36: =-L30*L31*Допущения!$B$89/Допущения!$B$88*Допущения!L40 -> -5371068.6
A37: Настольный теннис
A38: Фонд часов (за вычетом академии) | C38: =Допущения!$B$9*Допущения!$B$10*Допущения!$B$11-C8 -> 11058.545 | D38: =Допущения!$B$9*Допущения!$B$10*Допущения!$B$11-D8 -> 10802.182 | E38: =Допущения!$B$9*Допущения!$B$10*Допущения!$B$11-E8 -> 10597.091 | F38: =Допущения!$B$9*Допущения!$B$10*Допущения!$B$11-F8 -> 10597.091 | G38: =Допущения!$B$9*Допущения!$B$10*Допущения!$B$11-G8 -> 10597.091 | H38: =Допущения!$B$9*Допущения!$B$10*Допущения!$B$11-H8 -> 10597.091 | I38: =Допущения!$B$9*Допущения!$B$10*Допущения!$B$11-I8 -> 10597.091 | J38: =Допущения!$B$9*Допущения!$B$10*Допущения!$B$11-J8 -> 10597.091 | ... L38: =Допущения!$B$9*Допущения!$B$10*Допущения!$B$11-L8 -> 10597.091
A39: Загрузка (со сценарием) | C39: =MIN(Допущения!C66*Допущения!$B$20,Допущения!$B$12) -> 0.24 | D39: =MIN(Допущения!D66*Допущения!$B$20,Допущения!$B$12) -> 0.31 | E39: =MIN(Допущения!E66*Допущения!$B$20,Допущения!$B$12) -> 0.35 | F39: =MIN(Допущения!F66*Допущения!$B$20,Допущения!$B$12) -> 0.36 | G39: =MIN(Допущения!G66*Допущения!$B$20,Допущения!$B$12) -> 0.37 | H39: =MIN(Допущения!H66*Допущения!$B$20,Допущения!$B$12) -> 0.38 | I39: =MIN(Допущения!I66*Допущения!$B$20,Допущения!$B$12) -> 0.39 | J39: =MIN(Допущения!J66*Допущения!$B$20,Допущения!$B$12) -> 0.39 | ... L39: =MIN(Допущения!L66*Допущения!$B$20,Допущения!$B$12) -> 0.39
A40: Продано корт-часов | C40: =C38*C39 -> 2654.0509 | D40: =D38*D39 -> 3348.6764 | E40: =E38*E39 -> 3708.9818 | F40: =F38*F39 -> 3814.9527 | G40: =G38*G39 -> 3920.9236 | H40: =H38*H39 -> 4026.8945 | I40: =I38*I39 -> 4132.8655 | J40: =J38*J39 -> 4132.8655 | ... L40: =L38*L39 -> 4132.8655
A41: Доля групповых (эфф.) | C41: =IF(Допущения!$B$9>=Допущения!$B$93,Допущения!$B$90,0) -> 0.3 | D41: =IF(Допущения!$B$9>=Допущения!$B$93,Допущения!$B$90,0) -> 0.3 | E41: =IF(Допущения!$B$9>=Допущения!$B$93,Допущения!$B$90,0) -> 0.3 | F41: =IF(Допущения!$B$9>=Допущения!$B$93,Допущения!$B$90,0) -> 0.3 | G41: =IF(Допущения!$B$9>=Допущения!$B$93,Допущения!$B$90,0) -> 0.3 | H41: =IF(Допущения!$B$9>=Допущения!$B$93,Допущения!$B$90,0) -> 0.3 | I41: =IF(Допущения!$B$9>=Допущения!$B$93,Допущения!$B$90,0) -> 0.3 | J41: =IF(Допущения!$B$9>=Допущения!$B$93,Допущения!$B$90,0) -> 0.3 | ... L41: =IF(Допущения!$B$9>=Допущения!$B$93,Допущения!$B$90,0) -> 0.3
...

Sheet OPEX
A1: ОПЕРАЦИОННЫЕ РАСХОДЫ, ₽/ГОД
A3: Показатель | C3: Год 1 | D3: Год 2 | E3: Год 3 | F3: Год 4 | G3: Год 5 | H3: Год 6 | I3: Год 7 | J3: Год 8 | K3: Год 9 | L3: Год 10
A4: Электроэнергия | C4: =Допущения!$B$140*Допущения!$B$141*12*Допущения!C41 -> 5292000 | D4: =Допущения!$B$140*Допущения!$B$141*12*Допущения!D41 -> 5662440 | E4: =Допущения!$B$140*Допущения!$B$141*12*Допущения!E41 -> 6058810.8 | F4: =Допущения!$B$140*Допущения!$B$141*12*Допущения!F41 -> 6482927.6 | G4: =Допущения!$B$140*Допущения!$B$141*12*Допущения!G41 -> 6936732.5 | H4: =Допущения!$B$140*Допущения!$B$141*12*Допущения!H41 -> 7422303.8 | I4: =Допущения!$B$140*Допущения!$B$141*12*Допущения!I41 -> 7941865 | J4: =Допущения!$B$140*Допущения!$B$141*12*Допущения!J41 -> 8497795.6 | ... L4: =Допущения!$B$140*Допущения!$B$141*12*Допущения!L41 -> 9729126.2
A5: Вода | C5: =Допущения!$B$142*12*Допущения!C40 -> 600000 | D5: =Допущения!$B$142*12*Допущения!D40 -> 636000 | E5: =Допущения!$B$142*12*Допущения!E40 -> 674160 | F5: =Допущения!$B$142*12*Допущения!F40 -> 714609.6 | G5: =Допущения!$B$142*12*Допущения!G40 -> 757486.18 | H5: =Допущения!$B$142*12*Допущения!H40 -> 802935.35 | I5: =Допущения!$B$142*12*Допущения!I40 -> 851111.47 | J5: =Допущения!$B$142*12*Допущения!J40 -> 902178.16 | ... L5: =Допущения!$B$142*12*Допущения!L40 -> 1013687.4
A6: Маркетинг | C6: =Допущения!$B$143*12*Допущения!C40 -> 4200000 | D6: =Допущения!$B$143*12*Допущения!D40 -> 4452000 | E6: =Допущения!$B$143*12*Допущения!E40 -> 4719120 | F6: =Допущения!$B$143*12*Допущения!F40 -> 5002267.2 | G6: =Допущения!$B$143*12*Допущения!G40 -> 5302403.2 | H6: =Допущения!$B$143*12*Допущения!H40 -> 5620547.4 | I6: =Допущения!$B$143*12*Допущения!I40 -> 5957780.3 | J6: =Допущения!$B$143*12*Допущения!J40 -> 6315247.1 | ... L6: =Допущения!$B$143*12*Допущения!L40 -> 7095811.6
A7: Софт и цифровые сервисы | C7: =Допущения!$B$144*12*Допущения!C40 -> 1200000 | D7: =Допущения!$B$144*12*Допущения!D40 -> 1272000 | E7: =Допущения!$B$144*12*Допущения!E40 -> 1348320 | F7: =Допущения!$B$144*12*Допущения!F40 -> 1429219.2 | G7: =Допущения!$B$144*12*Допущения!G40 -> 1514972.4 | H7: =Допущения!$B$144*12*Допущения!H40 -> 1605870.7 | I7: =Допущения!$B$144*12*Допущения!I40 -> 1702222.9 | J7: =Допущения!$B$144*12*Допущения!J40 -> 1804356.3 | ... L7: =Допущения!$B$144*12*Допущения!L40 -> 2027374.8
A8: Расходники | C8: =Допущения!$B$145*12*Допущения!C40 -> 1560000 | D8: =Допущения!$B$145*12*Допущения!D40 -> 1653600 | E8: =Допущения!$B$145*12*Допущения!E40 -> 1752816 | F8: =Допущения!$B$145*12*Допущения!F40 -> 1857985 | G8: =Допущения!$B$145*12*Допущения!G40 -> 1969464.1 | H8: =Допущения!$B$145*12*Допущения!H40 -> 2087631.9 | I8: =Допущения!$B$145*12*Допущения!I40 -> 2212889.8 | J8: =Допущения!$B$145*12*Допущения!J40 -> 2345663.2 | ... L8: =Допущения!$B$145*12*Допущения!L40 -> 2635587.2
A9: Обслуживание | C9: =Допущения!$B$146*12*Допущения!C40 -> 2040000 | D9: =Допущения!$B$146*12*Допущения!D40 -> 2162400 | E9: =Допущения!$B$146*12*Допущения!E40 -> 2292144 | F9: =Допущения!$B$146*12*Допущения!F40 -> 2429672.6 | G9: =Допущения!$B$146*12*Допущения!G40 -> 2575453 | H9: =Допущения!$B$146*12*Допущения!H40 -> 2729980.2 | I9: =Допущения!$B$146*12*Допущения!I40 -> 2893779 | J9: =Допущения!$B$146*12*Допущения!J40 -> 3067405.7 | ... L9: =Допущения!$B$146*12*Допущения!L40 -> 3446537.1
A10: Охрана | C10: =Допущения!$B$147*12*Допущения!C40 -> 1200000 | D10: =Допущения!$B$147*12*Допущения!D40 -> 1272000 | E10: =Допущения!$B$147*12*Допущения!E40 -> 1348320 | F10: =Допущения!$B$147*12*Допущения!F40 -> 1429219.2 | G10: =Допущения!$B$147*12*Допущения!G40 -> 1514972.4 | H10: =Допущения!$B$147*12*Допущения!H40 -> 1605870.7 | I10: =Допущения!$B$147*12*Допущения!I40 -> 1702222.9 | J10: =Допущения!$B$147*12*Допущения!J40 -> 1804356.3 | ... L10: =Допущения!$B$147*12*Допущения!L40 -> 2027374.8
A11: Страхование | C11: =Допущения!$B$148*12*Допущения!C40 -> 900000 | D11: =Допущения!$B$148*12*Допущения!D40 -> 954000 | E11: =Допущения!$B$148*12*Допущения!E40 -> 1011240 | F11: =Допущения!$B$148*12*Допущения!F40 -> 1071914.4 | G11: =Допущения!$B$148*12*Допущения!G40 -> 1136229.3 | H11: =Допущения!$B$148*12*Допущения!H40 -> 1204403 | I11: =Допущения!$B$148*12*Допущения!I40 -> 1276667.2 | J11: =Допущения!$B$148*12*Допущения!J40 -> 1353267.2 | ... L11: =Допущения!$B$148*12*Допущения!L40 -> 1520531.1
A12: Бухгалтерия | C12: =Допущения!$B$149*12*Допущения!C40 -> 720000 | D12: =Допущения!$B$149*12*Допущения!D40 -> 763200 | E12: =Допущения!$B$149*12*Допущения!E40 -> 808992 | F12: =Допущения!$B$149*12*Допущения!F40 -> 857531.52 | G12: =Допущения!$B$149*12*Допущения!G40 -> 908983.41 | H12: =Допущения!$B$149*12*Допущения!H40 -> 963522.42 | I12: =Допущения!$B$149*12*Допущения!I40 -> 1021333.8 | J12: =Допущения!$B$149*12*Допущения!J40 -> 1082613.8 | ... L12: =Допущения!$B$149*12*Допущения!L40 -> 1216424.9
A13: Прочие | C13: =Допущения!$B$150*12*Допущения!C40 -> 1560000 | D13: =Допущения!$B$150*12*Допущения!D40 -> 1653600 | E13: =Допущения!$B$150*12*Допущения!E40 -> 1752816 | F13: =Допущения!$B$150*12*Допущения!F40 -> 1857985 | G13: =Допущения!$B$150*12*Допущения!G40 -> 1969464.1 | H13: =Допущения!$B$150*12*Допущения!H40 -> 2087631.9 | I13: =Допущения!$B$150*12*Допущения!I40 -> 2212889.8 | J13: =Допущения!$B$150*12*Допущения!J40 -> 2345663.2 | ... L13: =Допущения!$B$150*12*Допущения!L40 -> 2635587.2
A14: OPEX итого | C14: =SUM(C4:C13) -> 19272000 | D14: =SUM(D4:D13) -> 20481240 | E14: =SUM(E4:E13) -> 21766739 | F14: =SUM(F4:F13) -> 23133331 | G14: =SUM(G4:G13) -> 24586160 | H14: =SUM(H4:H13) -> 26130697 | I14: =SUM(I4:I13) -> 27772762 | J14: =SUM(J4:J13) -> 29518547 | ... L14: =SUM(L4:L13) -> 33348042
A16: Поддерживающий CAPEX (с года 2) | C16: =0 -> 0 | D16: =Допущения!$B$151*CAPEX!$B$24 -> 3684528 | E16: =Допущения!$B$151*CAPEX!$B$24 -> 3684528 | F16: =Допущения!$B$151*CAPEX!$B$24 -> 3684528 | G16: =Допущения!$B$151*CAPEX!$B$24 -> 3684528 | H16: =Допущения!$B$151*CAPEX!$B$24 -> 3684528 | I16: =Допущения!$B$151*CAPEX!$B$24 -> 3684528 | J16: =Допущения!$B$151*CAPEX!$B$24 -> 3684528 | K16: =Допущения!$B$151*CAPEX!$B$24 -> 3684528 | L16: =Допущения!$B$151*CAPEX!$B$24 -> 3684528 | M16: 1,5% инвестиций без оборотки; вне EBITDA, входит в FCF и налоговую базу

Sheet PL
A1: ОТЧЁТ О ПРИБЫЛЯХ И УБЫТКАХ (УПРАВЛЕНЧЕСКИЙ), ₽
A3: Показатель | C3: Год 1 | D3: Год 2 | E3: Год 3 | F3: Год 4 | G3: Год 5 | H3: Год 6 | I3: Год 7 | J3: Год 8 | K3: Год 9 | L3: Год 10
A4: Выручка
A5: Аренда кортов | C5: =Выручка!C69 -> 35527236 | D5: =Выручка!D69 -> 49512361 | E5: =Выручка!E69 -> 54728194 | F5: =Выручка!F69 -> 59631804 | G5: =Выручка!G69 -> 63782168 | H5: =Выручка!H69 -> 68198490 | I5: =Выручка!I69 -> 72896988 | J5: =Выручка!J69 -> 76541837 | ... L5: =Выручка!L69 -> 84387375
A6: Индивидуальные тренировки | C6: =Выручка!C70 -> 11886831 | D6: =Выручка!D70 -> 16487154 | E6: =Выручка!E70 -> 18345690 | F6: =Выручка!F70 -> 19985528 | G6: =Выручка!G70 -> 21393771 | H6: =Выручка!H70 -> 22892874 | I6: =Выручка!I70 -> 24488403 | J6: =Выручка!J70 -> 25712823 | ... L6: =Выручка!L70 -> 28348388
A7: Групповые занятия | C7: =Выручка!C71 -> 38443927 | D7: =Выручка!D71 -> 53326915 | E7: =Выручка!E71 -> 59479643 | F7: =Выручка!F71 -> 64853140 | G7: =Выручка!G71 -> 69417370 | H7: =Выручка!H71 -> 74275891 | I7: =Выручка!I71 -> 79446720 | J7: =Выручка!J71 -> 83419056 | ... L7: =Выручка!L71 -> 91969509
A8: Детская академия | C8: =Выручка!C50 -> 8121600 | D8: =Выручка!D50 -> 15476160 | E8: =Выручка!E50 -> 23877504 | F8: =Выручка!F50 -> 25071379 | G8: =Выручка!G50 -> 26324948 | H8: =Выручка!H50 -> 27641196 | I8: =Выручка!I50 -> 29023255 | J8: =Выручка!J50 -> 30474418 | ... L8: =Выручка!L50 -> 33598046
A9: ОФП 55+ | C9: =Выручка!C55 -> 1310400 | D9: =Выручка!D55 -> 1719900 | E9: =Выручка!E55 -> 2046681 | F9: =Выручка!F55 -> 2149015 | G9: =Выручка!G55 -> 2256465.8 | H9: =Выручка!H55 -> 2369289.1 | I9: =Выручка!I55 -> 2487753.5 | J9: =Выручка!J55 -> 2612141.2 | ... L9: =Выручка!L55 -> 2879885.7
A10: Кафе | C10: =Выручка!C59 -> 7739359.5 | D10: =Выручка!D59 -> 10933902 | E10: =Выручка!E59 -> 12530089 | F10: =Выручка!F59 -> 13579771 | G10: =Выручка!G59 -> 14498240 | H10: =Выручка!H59 -> 15474607 | I10: =Выручка!I59 -> 16512364 | J10: =Выручка!J59 -> 17337982 | ... L10: =Выручка!L59 -> 19115125
A11: Pro-shop | C11: =Выручка!C62 -> 3600000 | D11: =Выручка!D62 -> 3780000 | E11: =Выручка!E62 -> 3969000 | F11: =Выручка!F62 -> 4167450 | G11: =Выручка!G62 -> 4375822.5 | H11: =Выручка!H62 -> 4594613.6 | I11: =Выручка!I62 -> 4824344.3 | J11: =Выручка!J62 -> 5065561.5 | ... L11: =Выручка!L62 -> 5584781.6
A12: События и корпоративы | C12: =Выручка!C64 -> 1980000 | D12: =Выручка!D64 -> 3465000 | E12: =Выручка!E64 -> 4365900 | F12: =Выручка!F64 -> 5348227.5 | G12: =Выручка!G64 -> 5615638.9 | H12: =Выручка!H64 -> 5896420.8 | I12: =Выручка!I64 -> 6191241.9 | J12: =Выручка!J64 -> 6500804 | ... L12: =Выручка!L64 -> 7167136.4
A13: Летние лагеря | C13: =Выручка!C66 -> 1500000 | D13: =Выручка!D66 -> 3150000 | E13: =Выручка!E66 -> 4134375 | F13: =Выручка!F66 -> 4341093.8 | G13: =Выручка!G66 -> 4558148.4 | H13: =Выручка!H66 -> 4786055.9 | I13: =Выручка!I66 -> 5025358.7 | J13: =Выручка!J66 -> 5276626.6 | ... L13: =Выручка!L66 -> 5817480.8
A14: ВЫРУЧКА ИТОГО | C14: =SUM(C5:C13) -> 1.1010935e+08 | D14: =SUM(D5:D13) -> 1.5785139e+08 | E14: =SUM(E5:E13) -> 1.8347708e+08 | F14: =SUM(F5:F13) -> 1.9912741e+08 | G14: =SUM(G5:G13) -> 2.1222257e+08 | H14: =SUM(H5:H13) -> 2.2612944e+08 | I14: =SUM(I5:I13) -> 2.4089643e+08 | J14: =SUM(J5:J13) -> 2.5294125e+08 | ... L14: =SUM(L5:L13) -> 2.7886773e+08
A15: Прямые расходы
A16: Прямые расходы (тренеры, фудкост, себестоимости) | C16: =Выручка!C74 -> -32170688 | D16: =Выручка!D74 -> -48549966 | E16: =Выручка!E74 -> -57407976 | F16: =Выручка!F74 -> -62180401 | G16: =Выручка!G74 -> -66429170 | H16: =Выручка!H74 -> -70958465 | I16: =Выручка!I74 -> -75786422 | J16: =Выручка!J74 -> -80002436 | ... L16: =Выручка!L74 -> -89157027
A17: Валовая прибыль | C17: =C14+C16 -> 77938666 | D17: =D14+D16 -> 1.0930143e+08 | E17: =E14+E16 -> 1.260691e+08 | F17: =F14+F16 -> 1.3694701e+08 | G17: =G14+G16 -> 1.457934e+08 | H17: =H14+H16 -> 1.5517097e+08 | I17: =I14+I16 -> 1.6511001e+08 | J17: =J14+J16 -> 1.7293881e+08 | ... L17: =L14+L16 -> 1.897107e+08
A18: Постоянные расходы
A19: ФОТ (штат + аутсорс) | C19: =-Персонал!C16 -> -15600000 | D19: =-Персонал!D16 -> -16536000 | E19: =-Персонал!E16 -> -17528160 | F19: =-Персонал!F16 -> -18579850 | G19: =-Персонал!G16 -> -19694641 | H19: =-Персонал!H16 -> -20876319 | I19: =-Персонал!I16 -> -22128898 | J19: =-Персонал!J16 -> -23456632 | ... L19: =-Персонал!L16 -> -26355872
A20: Страховые взносы | C20: =-Персонал!C17 -> -3312000 | D20: =-Персонал!D17 -> -3510720 | E20: =-Персонал!E17 -> -3721363.2 | F20: =-Персонал!F17 -> -3944645 | G20: =-Персонал!G17 -> -4181323.7 | H20: =-Персонал!H17 -> -4432203.1 | I20: =-Персонал!I17 -> -4698135.3 | J20: =-Персонал!J17 -> -4980023.4 | ... L20: =-Персонал!L17 -> -5595554.3
A21: OPEX | C21: =-OPEX!C14 -> -19272000 | D21: =-OPEX!D14 -> -20481240 | E21: =-OPEX!E14 -> -21766739 | F21: =-OPEX!F14 -> -23133331 | G21: =-OPEX!G14 -> -24586160 | H21: =-OPEX!H14 -> -26130697 | I21: =-OPEX!I14 -> -27772762 | J21: =-OPEX!J14 -> -29518547 | ... L21: =-OPEX!L14 -> -33348042
A22: НДС (кафе, pro-shop, события) | C22: =-(Выручка!C59+Выручка!C62+Выручка!C64)*Допущения!$B$33 -> -665967.97 | D22: =-(Выручка!D59+Выручка!D62+Выручка!D64)*Допущения!$B$33 -> -908945.08 | E22: =-(Выручка!E59+Выручка!E62+Выручка!E64)*Допущения!$B$33 -> -1043249.4 | F22: =-(Выручка!F59+Выручка!F62+Выручка!F64)*Допущения!$B$33 -> -1154772.4 | G22: =-(Выручка!G59+Выручка!G62+Выручка!G64)*Допущения!$B$33 -> -1224485.1 | H22: =-(Выручка!H59+Выручка!H62+Выручка!H64)*Допущения!$B$33 -> -1298282.1 | I22: =-(Выручка!I59+Выручка!I62+Выручка!I64)*Допущения!$B$33 -> -1376397.5 | J22: =-(Выручка!J59+Выручка!J62+Выручка!J64)*Допущения!$B$33 -> -1445217.4 | ... L22: =-(Выручка!L59+Выручка!L62+Выручка!L64)*Допущения!$B$33 -> -1593352.2
A23: Платёжная комиссия | C23: =-C14*Допущения!$B$31*Допущения!$B$32 -> -990984.18 | D23: =-D14*Допущения!$B$31*Допущения!$B$32 -> -1420662.5 | E23: =-E14*Допущения!$B$31*Допущения!$B$32 -> -1651293.7 | F23: =-F14*Допущения!$B$31*Допущения!$B$32 -> -1792146.7 | G23: =-G14*Допущения!$B$31*Допущения!$B$32 -> -1910003.2 | H23: =-H14*Допущения!$B$31*Допущения!$B$32 -> -2035164.9 | I23: =-I14*Допущения!$B$31*Допущения!$B$32 -> -2168067.9 | J23: =-J14*Допущения!$B$31*Допущения!$B$32 -> -2276471.2 | ... L23: =-L14*Допущения!$B$31*Допущения!$B$32 -> -2509809.6
A24: EBITDA | C24: =C17+C19+C20+C21+C22+C23 -> 38097714 | D24: =D17+D19+D20+D21+D22+D23 -> 66443858 | E24: =E17+E19+E20+E21+E22+E23 -> 80358295 | F24: =F17+F19+F20+F21+F22+F23 -> 88342263 | G24: =G17+G19+G20+G21+G22+G23 -> 94196790 | H24: =H17+H19+H20+H21+H22+H23 -> 1.003983e+08 | I24: =I17+I19+I20+I21+I22+I23 -> 1.0696575e+08 | J24: =J17+J19+J20+J21+J22+J23 -> 1.1126192e+08 | ... L24: =L17+L19+L20+L21+L22+L23 -> 1.2030807e+08
A25: Маржа EBITDA | C25: =C24/C14 -> 0.34599889 | D25: =D24/D14 -> 0.42092666 | E25: =E24/E14 -> 0.43797458 | F25: =F24/F14 -> 0.44364693 | G25: =G24/G14 -> 0.44385849 | H25: =H24/H14 -> 0.443986 | I25: =I24/I14 -> 0.44403209 | J25: =J24/J14 -> 0.43987259 | ... L25: =L24/L14 -> 0.43141626
A27: УСН «доходы − расходы»: CAPEX списан в год 1, перенос убытков
A28: Доходы | C28: =C14 -> 1.1010935e+08 | D28: =D14 -> 1.5785139e+08 | E28: =E14 -> 1.8347708e+08 | F28: =F14 -> 1.9912741e+08 | G28: =G14 -> 2.1222257e+08 | H28: =H14 -> 2.2612944e+08 | I28: =I14 -> 2.4089643e+08 | J28: =J14 -> 2.5294125e+08 | ... L28: =L14 -> 2.7886773e+08
A29: Расходы для УСН | C29: =-(C16+C19+C20+C21+C22+C23)+OPEX!C16+CAPEX!$B$24 -> 3.1764684e+08 | D29: =-(D16+D19+D20+D21+D22+D23)+OPEX!D16 -> 95092061 | E29: =-(E16+E19+E20+E21+E22+E23)+OPEX!E16 -> 1.0680331e+08 | F29: =-(F16+F19+F20+F21+F22+F23)+OPEX!F16 -> 1.1446967e+08 | G29: =-(G16+G19+G20+G21+G22+G23)+OPEX!G16 -> 1.2171031e+08 | H29: =-(H16+H19+H20+H21+H22+H23)+OPEX!H16 -> 1.2941566e+08 | I29: =-(I16+I19+I20+I21+I22+I23)+OPEX!I16 -> 1.3761521e+08 | J29: =-(J16+J19+J20+J21+J22+J23)+OPEX!J16 -> 1.4536385e+08 | K29: =-(K16+K19+K20+K21+K22+K23)+OPEX!K16 -> 1.5356465e+08 | L29: =-(L16+L19+L20+L21+L22+L23)+OPEX!L16 -> 1.6224418e+08 | M29: Прямые+ФОТ+взносы+OPEX+НДС+комиссия+поддерж.CAPEX; год 1 — списание инвестиций
A30: База (доходы − расходы) | C30: =C28-C29 -> -2.0753749e+08 | D30: =D28-D29 -> 62759330 | E30: =E28-E29 -> 76673767 | F30: =F28-F29 -> 84657735 | G30: =G28-G29 -> 90512262 | H30: =H28-H29 -> 96713776 | I30: =I28-I29 -> 1.0328122e+08 | J30: =J28-J29 -> 1.0757739e+08 | ... L30: =L28-L29 -> 1.1662354e+08
A31: Убыток прошлых лет (на начало) | C31: =0 -> 0 | D31: =C34 -> 2.0753749e+08 | E31: =D34 -> 1.4477816e+08 | F31: =E34 -> 68104389 | G31: =F34 -> 0 | H31: =G34 -> 0 | I31: =H34 -> 0 | J31: =I34 -> 0 | K31: =J34 -> 0 | L31: =K34 -> 0
A32: Использовано убытка | C32: =IF(C30>0,MIN(C31,C30),0) -> 0 | D32: =IF(D30>0,MIN(D31,D30),0) -> 62759330 | E32: =IF(E30>0,MIN(E31,E30),0) -> 76673767 | F32: =IF(F30>0,MIN(F31,F30),0) -> 68104389 | G32: =IF(G30>0,MIN(G31,G30),0) -> 0 | H32: =IF(H30>0,MIN(H31,H30),0) -> 0 | I32: =IF(I30>0,MIN(I31,I30),0) -> 0 | J32: =IF(J30>0,MIN(J31,J30),0) -> 0 | ... L32: =IF(L30>0,MIN(L31,L30),0) -> 0
A33: Налог УСН (мин. 1% от доходов) | C33: =IF(C30>0,MAX(Допущения!$B$28*(C30-C32),Допущения!$B$29*C28),Допущения!$B$29*C28) -> 1101093.5 | D33: =IF(D30>0,MAX(Допущения!$B$28*(D30-D32),Допущения!$B$29*D28),Допущения!$B$29*D28) -> 1578513.9 | E33: =IF(E30>0,MAX(Допущения!$B$28*(E30-E32),Допущения!$B$29*E28),Допущения!$B$29*E28) -> 1834770.8 | F33: =IF(F30>0,MAX(Допущения!$B$28*(F30-F32),Допущения!$B$29*F28),Допущения!$B$29*F28) -> 1991274.1 | G33: =IF(G30>0,MAX(Допущения!$B$28*(G30-G32),Допущения!$B$29*G28),Допущения!$B$29*G28) -> 6335858.4 | H33: =IF(H30>0,MAX(Допущения!$B$28*(H30-H32),Допущения!$B$29*H28),Допущения!$B$29*H28) -> 6769964.3 | I33: =IF(I30>0,MAX(Допущения!$B$28*(I30-I32),Допущения!$B$29*I28),Допущения!$B$29*I28) -> 7229685.2 | J33: =IF(J30>0,MAX(Допущения!$B$28*(J30-J32),Допущения!$B$29*J28),Допущения!$B$29*J28) -> 7530417.6 | ... L33: =IF(L30>0,MAX(Допущения!$B$28*(L30-L32),Допущения!$B$29*L28),Допущения!$B$29*L28) -> 8163648
A34: Убыток на конец | C34: =C31-C32+IF(C30<0,-C30,0) -> 2.0753749e+08 | D34: =D31-D32+IF(D30<0,-D30,0) -> 1.4477816e+08 | E34: =E31-E32+IF(E30<0,-E30,0) -> 68104389 | F34: =F31-F32+IF(F30<0,-F30,0) -> 0 | G34: =G31-G32+IF(G30<0,-G30,0) -> 0 | H34: =H31-H32+IF(H30<0,-H30,0) -> 0 | I34: =I31-I32+IF(I30<0,-I30,0) -> 0 | J34: =J31-J32+IF(J30<0,-J30,0) -> 0 | ... L34: =L31-L32+IF(L30<0,-L30,0) -> 0
A35: Чистый результат (EBITDA − налог) | C35: =C24-C33 -> 36996620 | D35: =D24-D33 -> 64865344 | E35: =E24-E33 -> 78523524 | F35: =F24-F33 -> 86350989 | G35: =G24-G33 -> 87860932 | H35: =H24-H33 -> 93628340 | I35: =I24-I33 -> 99736060 | J35: =J24-J33 -> 1.0373151e+08 | ... L35: =L24-L33 -> 1.1214442e+08

Sheet ДДС
A1: ДЕНЕЖНЫЙ ПОТОК И ИНВЕСТИЦИОННЫЕ МЕТРИКИ, ₽
A3: Показатель | B3: Год 0 (стройка) | C3: Год 1 | D3: Год 2 | E3: Год 3 | F3: Год 4 | G3: Год 5 | H3: Год 6 | I3: Год 7 | J3: Год 8 | K3: Год 9 | L3: Год 10
A4: Инвестиции | B4: =-CAPEX!$B$26 -> -2.516352e+08
A5: EBITDA | C5: =PL!C24 -> 38097714 | D5: =PL!D24 -> 66443858 | E5: =PL!E24 -> 80358295 | F5: =PL!F24 -> 88342263 | G5: =PL!G24 -> 94196790 | H5: =PL!H24 -> 1.003983e+08 | I5: =PL!I24 -> 1.0696575e+08 | J5: =PL!J24 -> 1.1126192e+08 | ... L5: =PL!L24 -> 1.2030807e+08
A6: Налог УСН | C6: =-PL!C33 -> -1101093.5 | D6: =-PL!D33 -> -1578513.9 | E6: =-PL!E33 -> -1834770.8 | F6: =-PL!F33 -> -1991274.1 | G6: =-PL!G33 -> -6335858.4 | H6: =-PL!H33 -> -6769964.3 | I6: =-PL!I33 -> -7229685.2 | J6: =-PL!J33 -> -7530417.6 | ... L6: =-PL!L33 -> -8163648
A7: Поддерживающий CAPEX | C7: =-OPEX!C16 -> 0 | D7: =-OPEX!D16 -> -3684528 | E7: =-OPEX!E16 -> -3684528 | F7: =-OPEX!F16 -> -3684528 | G7: =-OPEX!G16 -> -3684528 | H7: =-OPEX!H16 -> -3684528 | I7: =-OPEX!I16 -> -3684528 | J7: =-OPEX!J16 -> -3684528 | ... L7: =-OPEX!L16 -> -3684528
A8: Свободный денежный поток (FCF) | B8: =B4 -> -2.516352e+08 | C8: =C5+C6+C7 -> 36996620 | D8: =D5+D6+D7 -> 61180816 | E8: =E5+E6+E7 -> 74838996 | F8: =F5+F6+F7 -> 82666461 | G8: =G5+G6+G7 -> 84176404 | H8: =H5+H6+H7 -> 89943812 | I8: =I5+I6+I7 -> 96051532 | J8: =J5+J6+J7 -> 1.0004698e+08 | ... L8: =L5+L6+L7 -> 1.084599e+08
A9: Накопленный поток | B9: =B8 -> -2.516352e+08 | C9: =B9+C8 -> -2.1463858e+08 | D9: =C9+D8 -> -1.5345776e+08 | E9: =D9+E8 -> -78618767 | F9: =E9+F8 -> 4047693.7 | G9: =F9+G8 -> 88224098 | H9: =G9+H8 -> 1.7816791e+08 | I9: =H9+I8 -> 2.7421944e+08 | J9: =I9+J8 -> 3.7426642e+08 | ... L9: =K9+L8 -> 5.8690832e+08
A10: Дисконт-фактор | B10: 1 | C10: =1/(1+Допущения!$B$34)^1 -> 0.84745763 | D10: =1/(1+Допущения!$B$34)^2 -> 0.71818443 | E10: =1/(1+Допущения!$B$34)^3 -> 0.60863087 | F10: =1/(1+Допущения!$B$34)^4 -> 0.51578888 | G10: =1/(1+Допущения!$B$34)^5 -> 0.43710922 | H10: =1/(1+Допущения!$B$34)^6 -> 0.37043154 | I10: =1/(1+Допущения!$B$34)^7 -> 0.31392503 | J10: =1/(1+Допущения!$B$34)^8 -> 0.26603816 | K10: =1/(1+Допущения!$B$34)^9 -> 0.22545607 | L10: =1/(1+Допущения!$B$34)^10 -> 0.19106447
A12: МЕТРИКИ
A13: Терминальная стоимость (EV/EBITDA × EBITDA г.10) | B13: =Допущения!$B$35*L5 -> 6.0154036e+08
A14: Потоки с ТС (для IRR) | B14: =B8 -> -2.516352e+08 | C14: =C8 -> 36996620 | D14: =D8 -> 61180816 | E14: =E8 -> 74838996 | F14: =F8 -> 82666461 | G14: =G8 -> 84176404 | H14: =H8 -> 89943812 | I14: =I8 -> 96051532 | ... K14: =K8 -> 1.0418201e+08 | L14: =L8+B13 -> 7.1000025e+08
A15: NPV @18% (с ТС) | B15: =B8+SUMPRODUCT(C8:L8,C10:L10)+B13*L10 -> 1.9787063e+08
A16: NPV @18% (без ТС) | B16: =B15-B13*L10 -> 82937642
A17: IRR (с ТС) | B17: =IRR(B14:L14) -> 0.30610934
A18: IRR (без ТС) | B18: =IRR(B8:L8) -> 0.25329153
A19: Окупаемость от открытия, лет | B19: =IFERROR(SUMPRODUCT(--(C9:L9<0))+(-INDEX(C9:L9,SUMPRODUCT(--(C9:L9<0))))/INDEX(C8:L8,SUMPRODUCT(--(C9:L9<0))+1),">10") -> 3.9510358
A20: Окупаемость от старта проекта, лет | B20: =IFERROR(B19+1,">10") -> 4.9510358
A21: Год 0 — строительство (12 мес). Потоки годовые, финансирование собственными средствами, без долга.

Sheet Сценарии
A1: СРАВНЕНИЕ СЦЕНАРИЕВ (зафиксированный прогон; живой пересчёт — переключателем на «Допущениях»)
A3: Метрика | B3: Оптимистичный | C3: Средний | D3: Пессимистичный
A4: Выручка год 1, млн ₽ | B4: 132.61492 | C4: 110.10935 | D4: 83.990117
A5: Выручка год 3, млн ₽ | B5: 217.26169 | C5: 183.47708 | D5: 139.96077
A6: Выручка год 5, млн ₽ | B6: 251.53248 | C6: 212.22257 | D6: 161.86046
A7: Выручка год 10, млн ₽ | B7: 330.70072 | C7: 278.86773 | D7: 212.66862
A8: EBITDA год 3, млн ₽ | B8: 106.25558 | C8: 80.358295 | D8: 46.506056
A9: Маржа EBITDA год 3 | B9: 0.48906726 | C9: 0.43797458 | D9: 0.33227922
A10: EBITDA год 5, млн ₽ | B10: 124.27581 | C10: 94.19679 | D10: 55.14492
A11: Окупаемость от старта, лет | B11: 4.1200023 | C11: 4.9510358 | D11: 7.1417372
A12: Окупаемость от открытия, лет | B12: 3.1200023 | C12: 3.9510358 | D12: 6.1417372
A13: NPV @18% с ТС, млн ₽ | B13: 350.79887 | C13: 197.87063 | D13: 2.6850013
A14: NPV @18% без ТС, млн ₽ | B14: 198.14853 | C14: 82.937642 | D14: -63.482978
A15: IRR с ТС | B15: 0.38884459 | C15: 0.30610934 | D15: 0.18198976
A16: IRR без ТС | B16: 0.34468863 | C16: 0.25329153 | D16: 0.11592546
A18: ГОДОВЫЕ РЯДЫ ПО СЦЕНАРИЯМ, МЛН ₽
A19: Показатель | B19: Год 1 | C19: Год 2 | D19: Год 3 | E19: Год 4 | F19: Год 5 | G19: Год 6 | H19: Год 7 | I19: Год 8 | J19: Год 9 | K19: Год 10
A20: Оптимистичный: выручка | B20: 132.61492 | C20: 190.05143 | D20: 217.26169 | E20: 235.94513 | F20: 251.53248 | G20: 268.0887 | H20: 285.67171 | I20: 299.9553 | J20: 314.95306 | K20: 330.70072
A21: Оптимистичный: EBITDA | B21: 53.900109 | C21: 91.643061 | D21: 106.25558 | E21: 116.53767 | F21: 124.27581 | G21: 132.4774 | H21: 141.16823 | I21: 147.14088 | J21: 153.34543 | K21: 159.78935
A22: Оптимистичный: FCF | B22: 52.57396 | C22: 86.058019 | D22: 100.39844 | E22: 105.03781 | F22: 112.1499 | G22: 119.77737 | H22: 127.85984 | I22: 133.41441 | J22: 139.18463 | K22: 145.17748
A23: Средний: выручка | B23: 110.10935 | C23: 157.85139 | D23: 183.47708 | E23: 199.12741 | F23: 212.22257 | G23: 226.12944 | H23: 240.89643 | I23: 252.94125 | J23: 265.58831 | K23: 278.86773
A24: Средний: EBITDA | B24: 38.097714 | C24: 66.443858 | D24: 80.358295 | E24: 88.342263 | F24: 94.19679 | G24: 100.3983 | H24: 106.96575 | I24: 111.26192 | J24: 115.70819 | K24: 120.30807
A25: Средний: FCF | B25: 36.99662 | C25: 61.180816 | D25: 74.838996 | E25: 82.666461 | F25: 84.176404 | G25: 89.943812 | H25: 96.051532 | I25: 100.04698 | J25: 104.18201 | K25: 108.4599
A26: Пессимистичный: выручка | B26: 83.990117 | C26: 120.3845 | D26: 139.96077 | E26: 151.88093 | F26: 161.86046 | G26: 172.45824 | H26: 183.71115 | I26: 192.89671 | J26: 202.54154 | K26: 212.66862
A27: Пессимистичный: EBITDA | B27: 18.116806 | C27: 40.317146 | D27: 46.506056 | E27: 51.657858 | F27: 55.14492 | G27: 58.835814 | H27: 62.741203 | I27: 64.871025 | J27: 67.045315 | K27: 69.262464
A28: Пессимистичный: FCF | B28: 17.276905 | C28: 35.428772 | D28: 41.42192 | E28: 46.454521 | F28: 49.841788 | G28: 53.426703 | H28: 54.922708 | I28: 56.903442 | J28: 58.925532 | K28: 60.987481
A30: Сценарные множители: оптимистичный — загрузка ×1,15, цены +5%, спрос ×1,15; пессимистичный — загрузка ×0,80, цены −5%, спрос ×0,80.

Sheet Оптимизация
A1: ПЕРЕБОР КОМПОЗИЦИЙ КОРТОВ — 182 ВАРИАНТА В ПЛОЩАДНОМ БЮДЖЕТЕ 1711 М² (СРЕДНИЙ СЦЕНАРИЙ)
A3: Критерий — окупаемость от старта. Ограничения: панорамики ≥2, бадминтон ≥2, НТ ≥2, сингл 0–2; площади 231/147/110/50 м².
A4: Расчёт выполнен тем же алгоритмом, что и модель (Python-прогон); живая модель построена на выбранной композиции.
A6: Пан. | B6: Сингл | C6: Бадм. | D6: НТ | E6: м² | F6: CAPEX, млн | G6: Окуп., лет | H6: NPV, млн | I6: IRR | J6: EBITDA г.5, млн | K6: Выр. г.3, млн | L6: Комментарий
A7: 2 | B7: 0 | C7: 10 | D7: 2 | E7: 1662 | F7: 243.2112 | G7: 4.8446807 | H7: 213.79768 | I7: 0.3176108 | J7: 96.222101 | K7: 183.96786 | L7: Формальный максимум, но хрупкий: прибыль зависит от бадминтон-групп
A8: 2 | B8: 1 | C8: 9 | D8: 2 | E8: 1699 | F8: 245.3712 | G8: 4.8534877 | H8: 213.84991 | I8: 0.31666858 | J8: 96.611109 | K8: 184.24832
A9: 3 | B9: 0 | C9: 8 | D9: 2 | E9: 1673 | F9: 246.0192 | G9: 4.8761172 | H9: 209.03469 | I9: 0.31404266 | J9: 95.660096 | K9: 183.9384
A10: 3 | B10: 1 | C10: 7 | D10: 2 | E10: 1710 | F10: 248.1792 | G10: 4.8865157 | H10: 208.82859 | I10: 0.31298935 | J10: 95.995644 | K10: 184.15338
A11: 2 | B11: 0 | C11: 9 | D11: 5 | E11: 1702 | F11: 244.032 | G11: 4.8968427 | H11: 206.54204 | I11: 0.31310056 | J11: 95.061279 | K11: 189.19998
A12: 4 | B12: 0 | C12: 6 | D12: 2 | E12: 1684 | F12: 248.8272 | G12: 4.9111977 | H12: 203.77118 | I12: 0.31023411 | J12: 94.994417 | K12: 183.78598
A13: 5 | B13: 0 | C13: 4 | D13: 2 | E13: 1695 | F13: 251.6352 | G13: 4.9510358 | H13: 197.87063 | I13: 0.30610934 | J13: 94.19679 | K13: 183.47708 | L13: ← ВЫБРАНА: лучшая устойчивость к риску заполнения групп (стресс-тест ниже)
A14: 2 | B14: 0 | C14: 9 | D14: 4 | E14: 1652 | F14: 243.6864 | G14: 4.9870238 | H14: 193.45685 | I14: 0.30572683 | J14: 92.397049 | K14: 184.09154
A15: 2 | B15: 1 | C15: 8 | D15: 4 | E15: 1689 | F15: 245.8464 | G15: 4.9937256 | H15: 193.79788 | I15: 0.30502595 | J15: 92.846383 | K15: 184.42215
A16: 3 | B16: 0 | C16: 7 | D16: 4 | E16: 1663 | F16: 246.4944 | G16: 5.0169944 | H16: 189.19025 | I16: 0.30247028 | J16: 91.938411 | K16: 184.16149
A17: 3 | B17: 1 | C17: 6 | D17: 4 | E17: 1700 | F17: 248.6544 | G17: 5.0246965 | H17: 189.35321 | I17: 0.30169741 | J17: 92.350991 | K17: 184.44315
A18: 2 | B18: 0 | C18: 8 | D18: 7 | E18: 1692 | F18: 244.5072 | G18: 5.0479547 | H18: 185.4082 | I18: 0.30073897 | J18: 91.070437 | K18: 189.19148
A19: 4 | B19: 0 | C19: 5 | D19: 4 | E19: 1674 | F19: 249.3024 | G19: 5.0497471 | H19: 184.538 | I19: 0.29902978 | J19: 91.399978 | K19: 184.13323
A20: 4 | B20: 1 | C20: 4 | D20: 4 | E20: 1711 | F20: 251.4624 | G20: 5.0590596 | H20: 184.46107 | I20: 0.29815143 | J20: 91.763027 | K20: 184.34961 | L20: Микс v2 — для сравнения
A21: 3 | B21: 0 | C21: 6 | D21: 7 | E21: 1703 | F21: 247.3152 | G21: 5.0741737 | H21: 181.75469 | I21: 0.29785006 | J21: 90.739285 | K21: 189.39166
A22: 2 | B22: 0 | C22: 9 | D22: 3 | E22: 1602 | F22: 243.3408 | G22: 5.0827033 | H22: 180.13702 | I22: 0.29811683 | J22: 89.683802 | K22: 178.94236
A23: 5 | B23: 0 | C23: 3 | D23: 4 | E23: 1685 | F23: 252.1104 | G23: 5.086392 | H23: 179.40366 | I23: 0.29535091 | J23: 90.7618 | K23: 183.98222
A24: 2 | B24: 1 | C24: 8 | D24: 3 | E24: 1639 | F24: 245.5008 | G24: 5.0899196 | H24: 180.34841 | I24: 0.29739558 | J24: 90.106116 | K24: 179.24805
A25: 2 | B25: 2 | C25: 7 | D25: 3 | E25: 1676 | F25: 247.6608 | G25: 5.0970199 | H25: 180.57019 | I25: 0.29669036 | J25: 90.530736 | K25: 179.54994
A26: 3 | B26: 0 | C26: 7 | D26: 3 | E26: 1613 | F26: 246.1488 | G26: 5.116346 | H26: 175.5332 | I26: 0.29468324 | J26: 89.155104 | K26: 178.93813
A27: 3 | B27: 1 | C27: 6 | D27: 3 | E27: 1650 | F27: 248.3088 | G27: 5.1251731 | H27: 175.51278 | I27: 0.29385904 | J27: 89.529509 | K27: 179.18255
A28: 3 | B28: 2 | C28: 5 | D28: 3 | E28: 1687 | F28: 250.4688 | G28: 5.1341847 | H28: 175.46154 | I28: 0.29302874 | J28: 89.89772 | K28: 179.41168
A29: 2 | B29: 0 | C29: 8 | D29: 6 | E29: 1642 | F29: 244.1616 | G29: 5.1429679 | H29: 172.62275 | I29: 0.29338918 | J29: 88.468858 | K29: 184.13348
A30: 2 | B30: 1 | C30: 7 | D30: 6 | E30: 1679 | F30: 246.3216 | G30: 5.1475135 | H30: 173.18118 | I30: 0.29289919 | J30: 88.963599 | K30: 184.5021
A31: 4 | B31: 0 | C31: 5 | D31: 3 | E31: 1624 | F31: 248.9568 | G31: 5.153997 | H31: 170.45537 | I31: 0.29101132 | J31: 88.528282 | K31: 178.81515
A32: 4 | B32: 1 | C32: 4 | D32: 3 | E32: 1661 | F32: 251.1168 | G32: 5.1650278 | H32: 170.14079 | I32: 0.29005108 | J32: 88.837149 | K32: 178.97636
... A36: 2 | B36: 0 | C36: 9 | D36: 2 | E36: 1552 | F36: 242.9952 | G36: 5.1860622 | H36: 166.60021 | I36: 0.29027204 | J36: 86.910229 | K36: 173.74303
A38: СТРЕСС-ТЕСТ ДОПУЩЕНИЯ О ВЗРОСЛЫХ ГРУППАХ (окупаемость от старта, лет / NPV, млн ₽)
A39: Композиция (П/С/Б/НТ) | B39: База: группы 30% | D39: Бадм. группы 15% | F39: Без взрослых групп | H39: Вывод
A40: 2/0/10/2 | B40: 4.8446807 | C40: 213.79768 | D40: 5.4909371 | E40: 131.92883 | F40: 6.7223139 | G40: 30.804637 | H40: Лидер базы; провал без групп
A41: 3/0/8/2 | B41: 4.8761172 | C41: 209.03469 | D41: 5.381253 | E41: 143.77814 | F41: 6.4466898 | G41: 49.228411 | H41: Хорош в базе, середина в стрессах
A42: 4/0/6/2 | B42: 4.9111977 | C42: 203.77118 | D42: 5.2821041 | E42: 155.01847 | F42: 6.203262 | G42: 67.053122 | H42: Сбалансированный компромисс
A43: 5/0/4/2 | B43: 4.9510358 | C43: 197.87063 | D43: 5.1936326 | E43: 165.48373 | F43: 5.9887884 | G43: 84.469183 | H43: РЕКОМЕНДОВАН: минимаксное сожаление по трём мирам
A44: 4/1/4/4 | B44: 5.0590596 | C44: 184.46107 | D44: 5.3150877 | E44: 152.13024 | F44: 6.0349275 | G44: 81.592701 | H44: Микс v2: проигрывает во всех мирах
A45: 2/0/9/5 | B45: 4.8968427 | C45: 206.54204 | D45: 5.4884252 | E45: 132.34348 | F45: 6.5866621 | G45: 40.270116 | H45: Бадминтон+НТ: хрупкий
A47: ВЫВОД: формальный лидер 2/0/10/2 без групповых программ теряет ~1,9 года окупаемости и 183 млн NPV.
...
